Workbook

Sheet Overview
A1: MediaWave Streaming — Final Project Timeline
A2: ISM 6562 · Big Data for Business Applications · Project #10
A4: Key Dates | D4: Team Roles
A5: Day 1 (Kickoff) | B5: Friday, April 24, 2026 | D5: Juan | E5: Integration Lead + Stage 1 (HDFS) | F5: Has 16 GB machine. Docker + networking + HDFS.
A6: First integration checkpoint | B6: Sunday, April 26, 2026 | D6: Yusuke | E6: Stage 2 (Spark batch) | F6: Python/data fluency. Joins, aggregations, PySpark.
A7: Technical freeze target | B7: Friday, May 1, 2026 | D7: Quang | E7: Stage 3 (Kafka + Streaming) | F7: Distributed systems curiosity. Producer + consumer.
A8: Final report + slides PDF | B8: Monday, May 4, 2026 | D8: Alex | E8: Stage 4 (Airflow) + Data Quality | F8: Clean code, modular Python. DAGs, retries, SLAs.
A9: Final dry-run | B9: Tuesday, May 5, 2026 | D9: Helen | E9: PM + Writer | F9: Strong English writing. Report, slides, rehearsals.
A10: Submission + In-class presentation | B10: Wednesday, May 6, 2026
A13: Progress Summary
A14: Total tasks | B14: =COUNTA('Daily Tasks'!D:D)-1 -> 110 | D14: Ground rules
A15: Tasks marked done | B15: =COUNTIF('Daily Tasks'!F:F,"Done") -> 9 | D15: • Daily 10-min standup at 9 PM
A16: Completion % | B16: =IFERROR(B15/B14,0) -> 0.081818182 | D16: • Every person commits to GitHub every day (empty commits OK)
D17: • Every handoff is a 15-min video call, not a text message
D18: • End-of-day status in group chat: green / yellow / red

Sheet Daily Tasks
A1: Day | B1: Date | C1: Person | D1: Stage/Area | E1: Task | F1: Status | G1: Notes
A2: 1 | B2: Thu Apr 23 | C2: TEAM | D2: Kickoff | E2: 90-min kickoff call: claim Project #10 on Canvas, confirm roles, set standup time, create shared Drive
A3: 1 | B3: Fri Apr 24 | C3: Helen | D3: Repo setup | E3: Build folder structure with .gitkeep files; README skeleton with all section headers
A4: 1 | B4: Fri Apr 24 | C4: Juan | D4: Stage 1 | E4: Copy 4 weekly docker-compose files into docker-research/ | F4: Done
A5: 1 | B5: Fri Apr 24 | C5: Juan | D5: Stage 1 | E5: Build conflict table: every service, port, volume, network across 4 files (DO NOT write merged file yet) | F5: Done
A6: 1 | B6: Fri Apr 24 | C6: Yusuke | D6: Stage 2 | E6: Download all 5 MediaWave files + generate_data.py
A7: 1 | B7: Fri Apr 24 | C7: Yusuke | D7: Stage 2 | E7: Set up Python venv and install pyspark 3.5.0, pandas, jupyter
A8: 1 | B8: Fri Apr 24 | C8: Yusuke | D8: Stage 2 | E8: Read generate_data.py end-to-end carefully (single most valuable hour)
A9: 1 | B9: Fri Apr 24 | C9: Yusuke | D9: Stage 2 | E9: Add Stage 2 section to docs/design.md: columns, types, nullable fields, join keys per dataset
A10: 1 | B10: Fri Apr 24 | C10: Yusuke | D10: Stage 2 | E10: Smoke test: load user-profiles.csv.gz with Spark, print schema, show 5 rows
A11: 1 | B11: Fri Apr 24 | C11: Quang | D11: Stage 3 | E11: Re-read Week 10 Kafka materials; pip install kafka-python
A12: 1 | B12: Fri Apr 24 | C12: Quang | D12: Stage 3 | E12: Add Stage 3 section to docs/design.md: topic name, partitions, key design, retention, producer strategy
A13: 1 | B13: Fri Apr 24 | C13: Quang | D13: Stage 3 | E13: Write producers/event_producer.py skeleton that prints fake JSON events to stdout (no Kafka yet)
A14: 1 | B14: Fri Apr 24 | C14: Alex | D14: Stage 4 | E14: Re-read Week 11 Airflow materials
A15: 1 | B15: Fri Apr 24 | C15: Alex | D15: Stage 4 | E15: Add Stage 4 section to docs/design.md: DAG sketch, task list, dependencies, quality gate locations
A16: 1 | B16: Fri Apr 24 | C16: Alex | D16: Stage 4 | E16: Create src/common/quality.py with 3 functions: check_row_count, check_nulls, check_unique_key; validate in notebook
A17: 2 | B17: Sat Apr 25 | C17: Juan | D17: Stage 1 | E17: Start docker-compose.yml from Week 11 as base; add HDFS services on shared network mediawave-net with mem_limit | F17: Done
A18: 2 | B18: Sat Apr 25 | C18: Juan | D18: Stage 1 | E18: Add Spark services (spark-master, spark-worker) from Week 9 | F18: Done
A19: 2 | B19: Sat Apr 25 | C19: Juan | D19: Stage 1 | E19: Boot partial stack, verify HDFS UI at :9870 and Spark UI at :8080 | F19: Done
A20: 2 | B20: Sat Apr 25 | C20: Juan | D20: Stage 1 | E20: Smoke test: docker exec -it namenode hdfs dfs -mkdir /test && hdfs dfs -ls / | F20: Done
A21: 2 | B21: Sat Apr 25 | C21: Yusuke | D21: Stage 2 | E21: Create src/common/schemas.py with explicit StructType for all 5 datasets
A22: 2 | B22: Sat Apr 25 | C22: Yusuke | D22: Stage 2 | E22: Build notebooks/02-spark-transforms.ipynb: load each dataset with schema, show count/describe/null counts
A23: 2 | B23: Sat Apr 25 | C23: Yusuke | D23: Stage 2 | E23: Draft reusable clean_and_save function (dropDuplicates + dropna + write Parquet)
A24: 2 | B24: Sat Apr 25 | C24: Yusuke | D24: Stage 2 | E24: Apply cleaning to 2 simplest datasets (user-profiles, streaming-quality) → local ./curated/
A25: 2 | B25: Sat Apr 25 | C25: Quang | D25: Stage 3 | E25: Expand event_producer.py: read viewing-history.csv.gz, sort by timestamp, publish JSON to user-viewing-events
A26: 2 | B26: Sat Apr 25 | C26: Quang | D26: Stage 3 | E26: Verify via kafka-console-consumer; ~50 events/sec flowing
A27: 2 | B27: Sat Apr 25 | C27: Alex | D27: Stage 4 | E27: Install Airflow locally or via light Docker container
A28: 2 | B28: Sat Apr 25 | C28: Alex | D28: Stage 4 | E28: dags/batch_pipeline.py with 5 placeholder BashOperator tasks: ingest, validate, clean, join, aggregate
A29: 2 | B29: Sat Apr 25 | C29: Alex | D29: Stage 4 | E29: Config: schedule_interval=@daily, catchup=False, retries=2, retry_delay=5min; verify one successful run
A30: 2 | B30: Sat Apr 25 | C30: Helen | D30: Report | E30: First architecture diagram v1 → docs/architecture-diagram.png
A31: 2 | B31: Sat Apr 25 | C31: Helen | D31: Report | E31: Draft report sections 1 (Executive Summary) and 2 (Architecture Design)
A32: 3 | B32: Sun Apr 26 | C32: Juan | D32: Stage 1 | E32: Add Kafka (zookeeper + kafka) from Week 10 to docker-compose | F32: Done
A33: 3 | B33: Sun Apr 26 | C33: Juan | D33: Stage 1 | E33: Add Airflow (postgres + airflow) from Week 11 to docker-compose | F33: Done
A34: 3 | B34: Sun Apr 26 | C34: Juan | D34: Stage 1 | E34: Add profiles: ['full'] tags on Kafka + Airflow for lightweight mode
A35: 3 | B35: Sun Apr 26 | C35: Juan | D35: Stage 1 | E35: Create HDFS zones: /landing/{5 subfolders}, /curated, /analytics; load all 5 raw files via hdfs dfs -put | F35: Done
A36: 3 | B36: Sun Apr 26 | C36: Juan | D36: Stage 1 | E36: NOON HANDOFF: 15-min call with B to walk through reading HDFS from Spark container
A37: 3 | B37: Sun Apr 26 | C37: Juan | D37: Stage 1 | E37: Afternoon: draft README setup instructions
A38: 3 | B38: Sun Apr 26 | C38: Yusuke | D38: Stage 2 | E38: Update src/common/config.py: LANDING = hdfs://namenode:9000/landing, etc.
A39: 3 | B39: Sun Apr 26 | C39: Yusuke | D39: Stage 2 | E39: Move notebook into Spark container environment; run Day 2 code against HDFS paths (should work unchanged)
A40: 3 | B40: Sun Apr 26 | C40: Yusuke | D40: Stage 2 | E40: Clean remaining 3 datasets: viewing-history, content-catalog (JSON), user-interactions (JSON)
...

Sheet Per-Person Summary
A1: Task Counts by Person
A3: Person | B3: Role | C3: Total Tasks | D3: Done | E3: Progress %
A4: Juan | B4: Integration Lead + Stage 1 (HDFS) | C4: =COUNTIF('Daily Tasks'!C:C,"A") -> 0 | D4: =COUNTIFS('Daily Tasks'!C:C,"A",'Daily Tasks'!F:F,"Done") -> 0 | E4: =IFERROR(D4/C4,0) -> 0
A5: Yusuke | B5: Stage 2 (Spark batch) | C5: =COUNTIF('Daily Tasks'!C:C,"B") -> 0 | D5: =COUNTIFS('Daily Tasks'!C:C,"B",'Daily Tasks'!F:F,"Done") -> 0 | E5: =IFERROR(D5/C5,0) -> 0
A6: Quang | B6: Stage 3 (Kafka + Streaming) | C6: =COUNTIF('Daily Tasks'!C:C,"C") -> 0 | D6: =COUNTIFS('Daily Tasks'!C:C,"C",'Daily Tasks'!F:F,"Done") -> 0 | E6: =IFERROR(D6/C6,0) -> 0
A7: Alex | B7: Stage 4 (Airflow) + Data Quality | C7: =COUNTIF('Daily Tasks'!C:C,"D") -> 0 | D7: =COUNTIFS('Daily Tasks'!C:C,"D",'Daily Tasks'!F:F,"Done") -> 0 | E7: =IFERROR(D7/C7,0) -> 0
A8: Helen | B8: PM + Writer + Presenter | C8: =COUNTIF('Daily Tasks'!C:C,"E") -> 0 | D8: =COUNTIFS('Daily Tasks'!C:C,"E",'Daily Tasks'!F:F,"Done") -> 0 | E8: =IFERROR(D8/C8,0) -> 0
A9: TEAM | B9: Team-wide tasks | C9: =COUNTIF('Daily Tasks'!C:C,"TEAM") -> 8 | D9: =COUNTIFS('Daily Tasks'!C:C,"TEAM",'Daily Tasks'!F:F,"Done") -> 0 | E9: =IFERROR(D9/C9,0) -> 0
A10: TOTAL | C10: =SUM(C4:C9) -> 8 | D10: =SUM(D4:D9) -> 0 | E10: =IFERROR(D10/C10,0) -> 0
A12: Task Counts by Day
A14: Day | B14: Date | C14: Total | D14: Done | E14: Progress %
A15: 1 | B15: Fri Apr 24 | C15: =COUNTIF('Daily Tasks'!A:A,1) -> 15 | D15: =COUNTIFS('Daily Tasks'!A:A,1,'Daily Tasks'!F:F,"Done") -> 2 | E15: =IFERROR(D15/C15,0) -> 0.13333333
A16: 2 | B16: Sat Apr 25 | C16: =COUNTIF('Daily Tasks'!A:A,2) -> 15 | D16: =COUNTIFS('Daily Tasks'!A:A,2,'Daily Tasks'!F:F,"Done") -> 4 | E16: =IFERROR(D16/C16,0) -> 0.26666667
A17: 3 | B17: Sun Apr 26 | C17: =COUNTIF('Daily Tasks'!A:A,3) -> 17 | D17: =COUNTIFS('Daily Tasks'!A:A,3,'Daily Tasks'!F:F,"Done") -> 3 | E17: =IFERROR(D17/C17,0) -> 0.17647059
A18: 4 | B18: Mon Apr 27 | C18: =COUNTIF('Daily Tasks'!A:A,4) -> 13 | D18: =COUNTIFS('Daily Tasks'!A:A,4,'Daily Tasks'!F:F,"Done") -> 0 | E18: =IFERROR(D18/C18,0) -> 0
A19: 5 | B19: Tue Apr 28 | C19: =COUNTIF('Daily Tasks'!A:A,5) -> 17 | D19: =COUNTIFS('Daily Tasks'!A:A,5,'Daily Tasks'!F:F,"Done") -> 0 | E19: =IFERROR(D19/C19,0) -> 0
A20: 6 | B20: Wed Apr 29 | C20: =COUNTIF('Daily Tasks'!A:A,6) -> 11 | D20: =COUNTIFS('Daily Tasks'!A:A,6,'Daily Tasks'!F:F,"Done") -> 0 | E20: =IFERROR(D20/C20,0) -> 0
A21: 7 | B21: Thu Apr 30 | C21: =COUNTIF('Daily Tasks'!A:A,7) -> 7 | D21: =COUNTIFS('Daily Tasks'!A:A,7,'Daily Tasks'!F:F,"Done") -> 0 | E21: =IFERROR(D21/C21,0) -> 0
A22: 8 | B22: Fri May 1 | C22: =COUNTIF('Daily Tasks'!A:A,8) -> 8 | D22: =COUNTIFS('Daily Tasks'!A:A,8,'Daily Tasks'!F:F,"Done") -> 0 | E22: =IFERROR(D22/C22,0) -> 0
A23: 9 | B23: Sat May 2 | C23: =COUNTIF('Daily Tasks'!A:A,9) -> 1 | D23: =COUNTIFS('Daily Tasks'!A:A,9,'Daily Tasks'!F:F,"Done") -> 0 | E23: =IFERROR(D23/C23,0) -> 0
A24: 10 | B24: Sun May 3 | C24: =COUNTIF('Daily Tasks'!A:A,10) -> 1 | D24: =COUNTIFS('Daily Tasks'!A:A,10,'Daily Tasks'!F:F,"Done") -> 0 | E24: =IFERROR(D24/C24,0) -> 0
A25: 11 | B25: Mon May 4 | C25: =COUNTIF('Daily Tasks'!A:A,11) -> 2 | D25: =COUNTIFS('Daily Tasks'!A:A,11,'Daily Tasks'!F:F,"Done") -> 0 | E25: =IFERROR(D25/C25,0) -> 0
A26: 12 | B26: Tue May 5 | C26: =COUNTIF('Daily Tasks'!A:A,12) -> 1 | D26: =COUNTIFS('Daily Tasks'!A:A,12,'Daily Tasks'!F:F,"Done") -> 0 | E26: =IFERROR(D26/C26,0) -> 0
A27: 13 | B27: Wed May 6 | C27: =COUNTIF('Daily Tasks'!A:A,13) -> 2 | D27: =COUNTIFS('Daily Tasks'!A:A,13,'Daily Tasks'!F:F,"Done") -> 0 | E27: =IFERROR(D27/C27,0) -> 0

Sheet Rubric Checklist
A1: Rubric Coverage Checklist
A2: Confirm ALL of these exist before submission. Check off as each is verified.
A4: Category | B4: Requirement | C4: Verified By | D4: Status
A5: Minimum | B5: 3+ data sources loaded into HDFS (you have 5) | C5: Juan
A6: Minimum | B6: 2+ Spark joins across different sources (you have 3) | C6: Yusuke
A7: Minimum | B7: 1+ Kafka topic with producer + Structured Streaming consumer | C7: Quang
A8: Minimum | B8: 1+ windowed aggregation in streaming | C8: Quang
A9: Minimum | B9: 1+ Airflow DAG with 4+ tasks and dependencies | C9: Alex
A10: Minimum | B10: 1+ data quality gate in Airflow | C10: Alex
A11: Minimum | B11: Working docker-compose.yml (docker compose up -d) | C11: Juan
A12: Minimum | B12: Pipeline is idempotent (run twice, same result) | C12: Alex
A13: Stage 1 (8 pts) | B13: Proper HDFS zone design (landing/curated/analytics) | C13: Juan
A14: Stage 1 (8 pts) | B14: File format choices justified per dataset | C14: Juan
A15: Stage 1 (8 pts) | B15: Replication strategy documented (one paragraph) | C15: Juan
A16: Stage 1 (8 pts) | B16: Data loaded correctly into all zones | C16: Juan
... A59: Creativity (10 pts) | B59: Tech decisions connected to business value | C59: Helen
A62: Rubric items verified: | B62: =COUNTIF(D5:D59,"Verified") & " of 55" -> 0 of 55
A63: Completion %: | B63: =COUNTIF(D5:D59,"Verified")/55 -> 0
